<?xml version="1.0"?>
<robot name="robot_mino" xmlns:xacro="http://www.ros.org/wiki/xacro">

  <!-- Badan -->
  <material name="dark_gray">
    <color rgba="0.5 0.5 0.5 1"/>
  </material>

  <!-- roda -->
  <material name="bright_red">
    <color rgba="0.1 0.1 0.1 1"/>
  </material>

  <!-- Lidar -->
  <material name="blue">
    <color rgba="1.0 0.5 0.0 1"/>
  </material>

  <xacro:property name="wheel_radius" value="0.026"/>
  <xacro:property name="wheel_separation" value="0.179"/>
  <xacro:property name="wheel_width" value="0.02"/>
  <xacro:property name="base_length" value="0.20"/>
  <xacro:property name="base_width" value="0.15"/>
  <xacro:property name="base_height" value="0.05"/>

  <link name="base_footprint"/>

  <link name="base_link">
    <visual>
      <geometry><box size="${base_length} ${base_width} ${base_height}"/></geometry>
      <material name="dark_gray"/>
    </visual>
    <collision>
      <geometry><box size="${base_length} ${base_width} ${base_height}"/></geometry>
    </collision>
    <inertial>
      <mass value="1.5"/>
      <inertia ixx="0.01" ixy="0" ixz="0" iyy="0.01" iyz="0" izz="0.01"/>
    </inertial>
  </link>

  <joint name="base_footprint_joint" type="fixed">
    <parent link="base_footprint"/>
    <child link="base_link"/>
    <origin xyz="0 0 ${wheel_radius}" rpy="0 0 0"/>
  </joint>

  <xacro:macro name="wheel" params="prefix y_offset">
    <link name="${prefix}_wheel_link">
      <visual>
        <origin xyz="0 0 0" rpy="${pi/2} 0 0"/>
        <geometry><cylinder radius="${wheel_radius}" length="${wheel_width}"/></geometry>
        <material name="bright_red"/>
      </visual>
      <collision>
        <origin xyz="0 0 0" rpy="${pi/2} 0 0"/>
        <geometry><cylinder radius="${wheel_radius}" length="${wheel_width}"/></geometry>
      </collision>
      <inertial>
        <mass value="0.05"/>
        <inertia ixx="0.0001" ixy="0" ixz="0" iyy="0.0001" iyz="0" izz="0.0001"/>
      </inertial>
    </link>

    <joint name="${prefix}_wheel_joint" type="continuous">
      <parent link="base_link"/>
      <child link="${prefix}_wheel_link"/>
      <origin xyz="0 ${y_offset} -${wheel_radius}" rpy="0 0 0"/>
      <axis xyz="0 1 0"/>
    </joint>
  </xacro:macro>

  <xacro:wheel prefix="left"  y_offset="${wheel_separation/2}"/>
  <xacro:wheel prefix="right" y_offset="-${wheel_separation/2}"/>

  <link name="imu_link"/>
  <joint name="imu_joint" type="fixed">
    <parent link="base_link"/>
    <child link="imu_link"/>
    <origin xyz="0 0 0.02" rpy="0 0 0"/>
  </joint>

  <link name="lidar_link">
    <visual>
      <origin xyz="0 0 0" rpy="0 0 0"/>
      <geometry>
        <cylinder radius="0.03" length="0.025"/>
      </geometry>
      <material name="blue"/>
    </visual>
    <collision>
      <geometry>
        <cylinder radius="0.03" length="0.025"/>
      </geometry>
    </collision>
    <inertial>
      <mass value="0.1"/>
      <inertia ixx="0.0001" ixy="0" ixz="0" iyy="0.0001" iyz="0" izz="0.0001"/>
    </inertial>
  </link>

  <joint name="lidar_joint" type="fixed">
    <parent link="base_link"/>
    <child link="lidar_link"/>
    <origin xyz="0.06 0 0.0375" rpy="0 0 4.71239"/>
  </joint>

  <ros2_control name="RobotMinoSystem" type="system">
    <hardware>
      <plugin>topic_based_ros2_control/TopicBasedSystem</plugin>
      <param name="joint_commands_topic">/topic_based_joint_commands</param>
      <param name="joint_states_topic">/topic_based_joint_states</param>
      <param name="trigger_joint_command_threshold">-1</param>
    </hardware>
    <joint name="left_wheel_joint">
      <command_interface name="velocity"/>
      <state_interface name="position"/>
      <state_interface name="velocity"/>
    </joint>
    <joint name="right_wheel_joint">
      <command_interface name="velocity"/>
      <state_interface name="position"/>
      <state_interface name="velocity"/>
    </joint>
  </ros2_control>

</robot>